Workbook
Name UPDATE: 'Data Sheet'!$E$1

Sheet Ratio Analysis
B2: ="Ratio Anlaysis - "&'Data Sheet'!B1 -> Ratio Anlaysis - HINDUSTAN UNILEVER LTD
B3: Years | C3: ='Data Sheet'!B16 -> 42460 | D3: ='Data Sheet'!C16 -> 42825 | E3: ='Data Sheet'!D16 -> 43190 | F3: ='Data Sheet'!E16 -> 43555 | G3: ='Data Sheet'!F16 -> 43921 | H3: ='Data Sheet'!G16 -> 44286 | I3: ='Data Sheet'!H16 -> 44651 | J3: ='Data Sheet'!I16 -> 45016 | ... L3: ='Data Sheet'!K16 -> 45747 | M3: Trend | N3: Mean | O3: Median
B5: Sales Growth | D5: =IFERROR('Historical Financial Statement '!D7,0) -> 0.030323743 | E5: =IFERROR('Historical Financial Statement '!E7,0) -> 0.071859357 | F5: =IFERROR('Historical Financial Statement '!F7,0) -> 0.10592207 | G5: =IFERROR('Historical Financial Statement '!G7,0) -> 0.012032562 | H5: =IFERROR('Historical Financial Statement '!H7,0) -> 0.18211296 | I5: =IFERROR('Historical Financial Statement '!I7,0) -> 0.11520796 | J5: =IFERROR('Historical Financial Statement '!J7,0) -> 0.15509286 | K5: =IFERROR('Historical Financial Statement '!K7,0) -> 0.021723341 | L5: =IFERROR('Historical Financial Statement '!L7,0) -> 0.019791263 | N5: =IFERROR(AVERAGE(D5:L5),0) -> 0.07934068 | O5: =IFERROR(MEDIAN(C5:L5),0) -> 0.071859357
B6: EBITDA Growth | D6: =IFERROR('Historical Financial Statement '!D18/'Historical Financial Statement '!C18-1,0) -> 0.07072758 | E6: =IFERROR('Historical Financial Statement '!E18/'Historical Financial Statement '!D18-1,0) -> 0.18505057 | F6: =IFERROR('Historical Financial Statement '!F18/'Historical Financial Statement '!E18-1,0) -> 0.18415789 | G6: =IFERROR('Historical Financial Statement '!G18/'Historical Financial Statement '!F18-1,0) -> 0.11047297 | H6: =IFERROR('Historical Financial Statement '!H18/'Historical Financial Statement '!G18-1,0) -> 0.17898793 | I6: =IFERROR('Historical Financial Statement '!I18/'Historical Financial Statement '!H18-1,0) -> 0.10588336 | J6: =IFERROR('Historical Financial Statement '!J18/'Historical Financial Statement '!I18-1,0) -> 0.10033445 | K6: =IFERROR('Historical Financial Statement '!K18/'Historical Financial Statement '!J18-1,0) -> 0.036191419 | L6: =IFERROR('Historical Financial Statement '!L18/'Historical Financial Statement '!K18-1,0) -> 0.012552016 | N6: =IFERROR(AVERAGE(D6:L6),0) -> 0.10937313 | O6: =IFERROR(MEDIAN(C6:L6),0) -> 0.10588336
B7: EBT Growth | D7: =IFERROR('Historical Financial Statement '!D27/'Historical Financial Statement '!C27-1,0) -> 0.057942238 | E7: =IFERROR('Historical Financial Statement '!E27/'Historical Financial Statement '!D27-1,0) -> 0.18631633 | F7: =IFERROR('Historical Financial Statement '!F27/'Historical Financial Statement '!E27-1,0) -> 0.19114051 | G7: =IFERROR('Historical Financial Statement '!G27/'Historical Financial Statement '!F27-1,0) -> 0.055421396 | H7: =IFERROR('Historical Financial Statement '!H27/'Historical Financial Statement '!G27-1,0) -> 0.19379934 | I7: =IFERROR('Historical Financial Statement '!I27/'Historical Financial Statement '!H27-1,0) -> 0.11739339 | J7: =IFERROR('Historical Financial Statement '!J27/'Historical Financial Statement '!I27-1,0) -> 0.10600343 | K7: =IFERROR('Historical Financial Statement '!K27/'Historical Financial Statement '!J27-1,0) -> 0.016516749 | L7: =IFERROR('Historical Financial Statement '!L27/'Historical Financial Statement '!K27-1,0) -> -0.0012205355 | N7: =IFERROR(AVERAGE(D7:L7),0) -> 0.10259032 | O7: =IFERROR(MEDIAN(C7:L7),0) -> 0.10600343
B8: Net Profit Growth | D8: =IFERROR('Historical Financial Statement '!D33/'Historical Financial Statement '!C33-1,0) -> 0.059754434 | E8: =IFERROR('Historical Financial Statement '!E33/'Historical Financial Statement '!D33-1,0) -> 0.25489186 | F8: =IFERROR('Historical Financial Statement '!F33/'Historical Financial Statement '!E33-1,0) -> 0.17726713 | G8: =IFERROR('Historical Financial Statement '!G33/'Historical Financial Statement '!F33-1,0) -> 0.10352039 | H8: =IFERROR('Historical Financial Statement '!H33/'Historical Financial Statement '!G33-1,0) -> 0.23641819 | I8: =IFERROR('Historical Financial Statement '!I33/'Historical Financial Statement '!H33-1,0) -> 0.10780432 | J8: =IFERROR('Historical Financial Statement '!J33/'Historical Financial Statement '!I33-1,0) -> 0.11783697 | K8: =IFERROR('Historical Financial Statement '!K33/'Historical Financial Statement '!J33-1,0) -> -0.023723569 | L8: =IFERROR('Historical Financial Statement '!L33/'Historical Financial Statement '!K33-1,0) -> -0.012255679 | N8: =IFERROR(AVERAGE(D8:L8),0) -> 0.11350156 | O8: =IFERROR(MEDIAN(C8:L8),0) -> 0.10780432
B9: Dividend Growth | D9: =IFERROR('Historical Financial Statement '!D41/'Historical Financial Statement '!C41-1,0) -> 0.062303632 | E9: =IFERROR('Historical Financial Statement '!E41/'Historical Financial Statement '!D41-1,0) -> 0.17636188 | F9: =IFERROR('Historical Financial Statement '!F41/'Historical Financial Statement '!E41-1,0) -> 0.099898369 | G9: =IFERROR('Historical Financial Statement '!G41/'Historical Financial Statement '!F41-1,0) -> 0.13631114 | H9: =IFERROR('Historical Financial Statement '!H41/'Historical Financial Statement '!G41-1,0) -> 0.6238764 | I9: =IFERROR('Historical Financial Statement '!I41/'Historical Financial Statement '!H41-1,0) -> -0.16049383 | J9: =IFERROR('Historical Financial Statement '!J41/'Historical Financial Statement '!I41-1,0) -> 0.14705882 | K9: =IFERROR('Historical Financial Statement '!K41/'Historical Financial Statement '!J41-1,0) -> 0.076923077 | L9: =IFERROR('Historical Financial Statement '!L41/'Historical Financial Statement '!K41-1,0) -> 0.26190476 | N9: =IFERROR(AVERAGE(D9:L9),0) -> 0.15823825 | O9: =IFERROR(MEDIAN(C9:L9),0) -> 0.13631114
B11: Gross Margin | C11: =IFERROR('Historical Financial Statement '!C13,0) -> 0.43385323 | D11: =IFERROR('Historical Financial Statement '!D13,0) -> 0.43685544 | E11: =IFERROR('Historical Financial Statement '!E13,0) -> 0.45663244 | F11: =IFERROR('Historical Financial Statement '!F13,0) -> 0.46372424 | G11: =IFERROR('Historical Financial Statement '!G13,0) -> 0.48183898 | H11: =IFERROR('Historical Financial Statement '!H13,0) -> 0.46200136 | I11: =IFERROR('Historical Financial Statement '!I13,0) -> 0.44579186 | J11: =IFERROR('Historical Financial Statement '!J13,0) -> 0.41596236 | ... L11: =IFERROR('Historical Financial Statement '!L13,0) -> 0.45297128 | N11: =IFERROR(AVERAGE(C11:L11),0) -> 0.45059612 | O11: =IFERROR(MEDIAN(C11:L11),0) -> 0.45465063
B12: EBITDA Margin | C12: =IFERROR('Historical Financial Statement '!C19,0) -> 0.18362021 | D12: =IFERROR('Historical Financial Statement '!D19,0) -> 0.19082082 | E12: =IFERROR('Historical Financial Statement '!E19,0) -> 0.21097201 | F12: =IFERROR('Historical Financial Statement '!F19,0) -> 0.22589672 | G12: =IFERROR('Historical Financial Statement '!G19,0) -> 0.24786969 | H12: =IFERROR('Historical Financial Statement '!H19,0) -> 0.24721443 | I12: =IFERROR('Historical Financial Statement '!I19,0) -> 0.24514739 | J12: =IFERROR('Historical Financial Statement '!J19,0) -> 0.23352592 | ... L12: =IFERROR('Historical Financial Statement '!L19,0) -> 0.23515153 | N12: =IFERROR(AVERAGE(C12:L12),0) -> 0.22570515 | O12: =IFERROR(MEDIAN(C12:L12),0) -> 0.23433873
B13: EBIT Margin | C13: =IFERROR(('Historical Financial Statement '!C18-'Historical Financial Statement '!C24)/'Historical Financial Statement '!C6,0) -> 0.17265271 | D13: =IFERROR(('Historical Financial Statement '!D18-'Historical Financial Statement '!D24)/'Historical Financial Statement '!D6,0) -> 0.17779386 | E13: =IFERROR(('Historical Financial Statement '!E18-'Historical Financial Statement '!E24)/'Historical Financial Statement '!E6,0) -> 0.19634266 | F13: =IFERROR(('Historical Financial Statement '!F18-'Historical Financial Statement '!F24)/'Historical Financial Statement '!F6,0) -> 0.21152379 | G13: =IFERROR(('Historical Financial Statement '!G18-'Historical Financial Statement '!G24)/'Historical Financial Statement '!G6,0) -> 0.22268306 | H13: =IFERROR(('Historical Financial Statement '!H18-'Historical Financial Statement '!H24)/'Historical Financial Statement '!H6,0) -> 0.22437697 | I13: =IFERROR(('Historical Financial Statement '!I18-'Historical Financial Statement '!I24)/'Historical Financial Statement '!I6,0) -> 0.22434504 | J13: =IFERROR(('Historical Financial Statement '!J18-'Historical Financial Statement '!J24)/'Historical Financial Statement '!J6,0) -> 0.21475735 | ... L13: =IFERROR(('Historical Financial Statement '!L18-'Historical Financial Statement '!L24)/'Historical Financial Statement '!L6,0) -> 0.21368483 | N13: =IFERROR(AVERAGE(C13:L13),0) -> 0.20753471 | O13: =IFERROR(MEDIAN(C13:L13),0) -> 0.21422109
B14: EBT Margin | C14: =IFERROR('Historical Financial Statement '!C28,0) -> 0.17212453 | D14: =IFERROR('Historical Financial Statement '!D28,0) -> 0.17673844 | E14: =IFERROR('Historical Financial Statement '!E28,0) -> 0.1956112 | F14: =IFERROR('Historical Financial Statement '!F28,0) -> 0.2106843 | G14: =IFERROR('Historical Financial Statement '!G28,0) -> 0.21971696 | H14: =IFERROR('Historical Financial Statement '!H28,0) -> 0.22188909 | I14: =IFERROR('Historical Financial Statement '!I28,0) -> 0.22232391 | J14: =IFERROR('Historical Financial Statement '!J28,0) -> 0.21287554 | ... L14: =IFERROR('Historical Financial Statement '!L28,0) -> 0.20742701 | N14: =IFERROR(AVERAGE(C14:L14),0) -> 0.20511817 | O14: =IFERROR(MEDIAN(C14:L14),0) -> 0.21123753
B15: Net Profit Margin | C15: =IFERROR('Historical Financial Statement '!C34,0) -> 0.11386938 | D15: =IFERROR('Historical Financial Statement '!D34,0) -> 0.11712201 | E15: =IFERROR('Historical Financial Statement '!E34,0) -> 0.13712196 | F15: =IFERROR('Historical Financial Statement '!F34,0) -> 0.14596795 | G15: =IFERROR('Historical Financial Statement '!G34,0) -> 0.15916346 | H15: =IFERROR('Historical Financial Statement '!H34,0) -> 0.16647529 | I15: =IFERROR('Historical Financial Statement '!I34,0) -> 0.16537009 | J15: =IFERROR('Historical Financial Statement '!J34,0) -> 0.16003632 | ... L15: =IFERROR('Historical Financial Statement '!L34,0) -> 0.14811236 | N15: =IFERROR(AVERAGE(C15:L15),0) -> 0.14661566 | O15: =IFERROR(MEDIAN(C15:L15),0) -> 0.15051508
B17: SalesExpenses%Sales | C17: =IFERROR('Historical Financial Statement '!C16,0) -> 0.25023302 | D17: =IFERROR('Historical Financial Statement '!D16,0) -> 0.24603462 | E17: =IFERROR('Historical Financial Statement '!E16,0) -> 0.24566043 | F17: =IFERROR('Historical Financial Statement '!F16,0) -> 0.23782752 | G17: =IFERROR('Historical Financial Statement '!G16,0) -> 0.23396928 | H17: =IFERROR('Historical Financial Statement '!H16,0) -> 0.21478694 | I17: =IFERROR('Historical Financial Statement '!I16,0) -> 0.20064447 | J17: =IFERROR('Historical Financial Statement '!J16,0) -> 0.18243645 | ... L17: =IFERROR('Historical Financial Statement '!L16,0) -> 0.21781974 | N17: =IFERROR(AVERAGE(C17:L17),0) -> 0.22489097 | O17: =IFERROR(MEDIAN(C17:L17),0) -> 0.22673325
B18: Depreciation%Sales | C18: =IFERROR('Historical Financial Statement '!C25,0) -> 0.010967501 | D18: =IFERROR('Historical Financial Statement '!D25,0) -> 0.013026959 | E18: =IFERROR('Historical Financial Statement '!E25,0) -> 0.014629343 | F18: =IFERROR('Historical Financial Statement '!F25,0) -> 0.014372933 | G18: =IFERROR('Historical Financial Statement '!G25,0) -> 0.025186638 | H18: =IFERROR('Historical Financial Statement '!H25,0) -> 0.022837459 | I18: =IFERROR('Historical Financial Statement '!I25,0) -> 0.020802349 | J18: =IFERROR('Historical Financial Statement '!J25,0) -> 0.01876857 | ... L18: =IFERROR('Historical Financial Statement '!L25,0) -> 0.021466707 | N18: =IFERROR(AVERAGE(C18:L18),0) -> 0.018170432 | O18: =IFERROR(MEDIAN(C18:L18),0) -> 0.019207214
B19: OperatingIncome%Sales | C19: ='Ratio Analysis'!C13 -> 0.17265271 | D19: ='Ratio Analysis'!D13 -> 0.17779386 | E19: ='Ratio Analysis'!E13 -> 0.19634266 | F19: ='Ratio Analysis'!F13 -> 0.21152379 | G19: ='Ratio Analysis'!G13 -> 0.22268306 | H19: ='Ratio Analysis'!H13 -> 0.22437697 | I19: ='Ratio Analysis'!I13 -> 0.22434504 | J19: ='Ratio Analysis'!J13 -> 0.21475735 | ... L19: ='Ratio Analysis'!L13 -> 0.21368483 | N19: =IFERROR(AVERAGE(C19:L19),0) -> 0.20753471 | O19: =IFERROR(MEDIAN(C19:L19),0) -> 0.21422109
B21: Return on Capital Employed | C21: =IFERROR(('Historical Financial Statement '!C18-'Historical Financial Statement '!C24)/(SUM('Historical Financial Statement '!C48:C50)),0) -> 0.82325926 | D21: =IFERROR(('Historical Financial Statement '!D18-'Historical Financial Statement '!D24)/(SUM('Historical Financial Statement '!D48:D50)),0) -> 0.83976642 | E21: =IFERROR(('Historical Financial Statement '!E18-'Historical Financial Statement '!E24)/(SUM('Historical Financial Statement '!E48:E50)),0) -> 0.95852218 | F21: =IFERROR(('Historical Financial Statement '!F18-'Historical Financial Statement '!F24)/(SUM('Historical Financial Statement '!F48:F50)),0) -> 1.0438112 | G21: =IFERROR(('Historical Financial Statement '!G18-'Historical Financial Statement '!G24)/(SUM('Historical Financial Statement '!G48:G50)),0) -> 1.0765585 | H21: =IFERROR(('Historical Financial Statement '!H18-'Historical Financial Statement '!H24)/(SUM('Historical Financial Statement '!H48:H50)),0) -> 0.22133658 | I21: =IFERROR(('Historical Financial Statement '!I18-'Historical Financial Statement '!I24)/(SUM('Historical Financial Statement '!I48:I50)),0) -> 0.23483155 | J21: =IFERROR(('Historical Financial Statement '!J18-'Historical Financial Statement '!J24)/(SUM('Historical Financial Statement '!J48:J50)),0) -> 0.25250859 | ... L21: =IFERROR(('Historical Financial Statement '!L18-'Historical Financial Statement '!L24)/(SUM('Historical Financial Statement '!L48:L50)),0) -> 0.26421156 | N21: =IFERROR(AVERAGE(C21:L21),0) -> 0.59698815 | O21: =IFERROR(MEDIAN(C21:L21),0) -> 0.54373541
B22: Retained Earnings% | C22: =IFERROR('Historical Financial Statement '!C44,0) -> 0.057025921 | D22: =IFERROR('Historical Financial Statement '!D44,0) -> 0.054582904 | E22: =IFERROR('Historical Financial Statement '!E44,0) -> 0.11366434 | F22: =IFERROR('Historical Financial Statement '!F44,0) -> 0.17183688 | G22: =IFERROR('Historical Financial Statement '!G44,0) -> 0.14718888 | H22: =IFERROR('Historical Financial Statement '!H44,0) -> 0 | I22: =IFERROR('Historical Financial Statement '!I44,0) -> 0.078750144 | J22: =IFERROR('Historical Financial Statement '!J44,0) -> 0.054667354 | ... L22: =IFERROR('Historical Financial Statement '!L44,0) -> 0 | N22: =IFERROR(AVERAGE(C22:L22),0) -> 0.067771642 | O22: =IFERROR(MEDIAN(C22:L22),0) -> 0.055846638
B23: Return on Equity% | C23: =IFERROR('Historical Financial Statement '!C33/(SUM('Historical Financial Statement '!C48:C49)),0) -> 0.55758406 | D23: =IFERROR('Historical Financial Statement '!D33/(SUM('Historical Financial Statement '!D48:D49)),0) -> 0.57591934 | E23: =IFERROR('Historical Financial Statement '!E33/(SUM('Historical Financial Statement '!E48:E49)),0) -> 0.66941354 | F23: =IFERROR('Historical Financial Statement '!F33/(SUM('Historical Financial Statement '!F48:F49)),0) -> 0.72937587 | G23: =IFERROR('Historical Financial Statement '!G33/(SUM('Historical Financial Statement '!G48:G49)),0) -> 0.76947381 | H23: =IFERROR('Historical Financial Statement '!H33/(SUM('Historical Financial Statement '!H48:H49)),0) -> 0.16421949 | I23: =IFERROR('Historical Financial Statement '!I33/(SUM('Historical Financial Statement '!I48:I49)),0) -> 0.17677993 | J23: =IFERROR('Historical Financial Statement '!J33/(SUM('Historical Financial Statement '!J48:J49)),0) -> 0.19272821 | ... L23: =IFERROR('Historical Financial Statement '!L33/(SUM('Historical Financial Statement '!L48:L49)),0) -> 0.18924335 | N23: =IFERROR(AVERAGE(C23:L23),0) -> 0.42095359 | O23: =IFERROR(MEDIAN(C23:L23),0) -> 0.37515613
B24: Self Sustained Growth Rate | C24: =IFERROR(C22*C23,0) -> 0.031796744 | D24: =IFERROR(D22*D23,0) -> 0.03143535 | E24: =IFERROR(E22*E23,0) -> 0.076088449 | F24: =IFERROR(F22*F23,0) -> 0.12533367 | G24: =IFERROR(G22*G23,0) -> 0.11325799 | H24: =IFERROR(H22*H23,0) -> 0 | I24: =IFERROR(I22*I23,0) -> 0.013921445 | J24: =IFERROR(J22*J23,0) -> 0.010535941 | ... L24: =IFERROR(L22*L23,0) -> 0 | N24: =IFERROR(AVERAGE(C24:L24),0) -> 0.040236959 | O24: =IFERROR(MEDIAN(C24:L24),0) -> 0.022678397
B25: Interest Coverage Ratio | C25: =IFERROR(('Historical Financial Statement '!C18-'Historical Financial Statement '!C24)/'Historical Financial Statement '!C21,0) -> 326.88235 | D25: =IFERROR(('Historical Financial Statement '!D18-'Historical Financial Statement '!D24)/'Historical Financial Statement '!D21,0) -> 168.45714 | E25: =IFERROR(('Historical Financial Statement '!E18-'Historical Financial Statement '!E24)/'Historical Financial Statement '!E21,0) -> 268.42308 | F25: =IFERROR(('Historical Financial Statement '!F18-'Historical Financial Statement '!F24)/'Historical Financial Statement '!F21,0) -> 251.9697 | G25: =IFERROR(('Historical Financial Statement '!G18-'Historical Financial Statement '!G24)/'Historical Financial Statement '!G21,0) -> 75.076271 | H25: =IFERROR(('Historical Financial Statement '!H18-'Historical Financial Statement '!H24)/'Historical Financial Statement '!H21,0) -> 90.188034 | I25: =IFERROR(('Historical Financial Statement '!I18-'Historical Financial Statement '!I24)/'Historical Financial Statement '!I21,0) -> 111 | J25: =IFERROR(('Historical Financial Statement '!J18-'Historical Financial Statement '!J24)/'Historical Financial Statement '!J21,0) -> 114.12281 | ... L25: =IFERROR(('Historical Financial Statement '!L18-'Historical Financial Statement '!L24)/'Historical Financial Statement '!L21,0) -> 34.146835 | N25: =IFERROR(AVERAGE(C25:L25),0) -> 148.05147 | O25: =IFERROR(MEDIAN(C25:L25),0) -> 112.5614
B27: Debtor Turnover Ratio | C27: =IFERROR('Historical Financial Statement '!C6/'Historical Financial Statement '!C60,0) -> 25.463608 | D27: =IFERROR('Historical Financial Statement '!D6/'Historical Financial Statement '!D60,0) -> 30.564055 | E27: =IFERROR('Historical Financial Statement '!E6/'Historical Financial Statement '!E60,0) -> 27.133588 | F27: =IFERROR('Historical Financial Statement '!F6/'Historical Financial Statement '!F60,0) -> 21.646476 | G27: =IFERROR('Historical Financial Statement '!G6/'Historical Financial Statement '!G60,0) -> 34.624021 | H27: =IFERROR('Historical Financial Statement '!H6/'Historical Financial Statement '!H60,0) -> 26.750853 | I27: =IFERROR('Historical Financial Statement '!I6/'Historical Financial Statement '!I60,0) -> 23.455277 | J27: =IFERROR('Historical Financial Statement '!J6/'Historical Financial Statement '!J60,0) -> 19.675219 | ... L27: =IFERROR('Historical Financial Statement '!L6/'Historical Financial Statement '!L60,0) -> 16.528149 | N27: =IFERROR(AVERAGE(C27:L27),0) -> 24.64939 | O27: =IFERROR(MEDIAN(C27:L27),0) -> 24.459442
B28: Creditor Turnover Ratio | C28: =IFERROR('Historical Financial Statement '!C6/'Historical Financial Statement '!C51,0) -> 4.0017406 | D28: =IFERROR('Historical Financial Statement '!D6/'Historical Financial Statement '!D51,0) -> 3.8183074 | E28: =IFERROR('Historical Financial Statement '!E6/'Historical Financial Statement '!E51,0) -> 3.3593233 | F28: =IFERROR('Historical Financial Statement '!F6/'Historical Financial Statement '!F51,0) -> 3.6865798 | G28: =IFERROR('Historical Financial Statement '!G6/'Historical Financial Statement '!G51,0) -> 3.3363804 | H28: =IFERROR('Historical Financial Statement '!H6/'Historical Financial Statement '!H51,0) -> 2.2324124 | I28: =IFERROR('Historical Financial Statement '!I6/'Historical Financial Statement '!I51,0) -> 2.5706303 | J28: =IFERROR('Historical Financial Statement '!J6/'Historical Financial Statement '!J51,0) -> 2.8106152 | ... L28: =IFERROR('Historical Financial Statement '!L6/'Historical Financial Statement '!L51,0) -> 2.1907125 | N28: =IFERROR(AVERAGE(C28:L28),0) -> 3.0406981 | O28: =IFERROR(MEDIAN(C28:L28),0) -> 3.0734978
B29: Inventory Turnover | C29: =IFERROR('Historical Financial Statement '!C6/'Historical Financial Statement '!C61,0) -> 11.807043 | D29: =IFERROR('Historical Financial Statement '!D6/'Historical Financial Statement '!D61,0) -> 13.050767 | E29: =IFERROR('Historical Financial Statement '!E6/'Historical Financial Statement '!E61,0) -> 14.144449 | F29: =IFERROR('Historical Financial Statement '!F6/'Historical Financial Statement '!F61,0) -> 15.27195 | G29: =IFERROR('Historical Financial Statement '!G6/'Historical Financial Statement '!G61,0) -> 14.377665 | H29: =IFERROR('Historical Financial Statement '!H6/'Historical Financial Statement '!H61,0) -> 13.139983 | I29: =IFERROR('Historical Financial Statement '!I6/'Historical Financial Statement '!I61,0) -> 12.804199 | J29: =IFERROR('Historical Financial Statement '!J6/'Historical Financial Statement '!J61,0) -> 14.250765 | ... L29: =IFERROR('Historical Financial Statement '!L6/'Historical Financial Statement '!L61,0) -> 14.296942 | N29: =IFERROR(AVERAGE(C29:L29),0) -> 13.853312 | O29: =IFERROR(MEDIAN(C29:L29),0) -> 14.197607
B30: Fixed Asset Turnover | C30: =IFERROR('Historical Financial Statement '!C6/'Historical Financial Statement '!C54,0) -> 9.8790669 | D30: =IFERROR('Historical Financial Statement '!D6/'Historical Financial Statement '!D54,0) -> 7.5044128 | E30: =IFERROR('Historical Financial Statement '!E6/'Historical Financial Statement '!E54,0) -> 7.8500442 | F30: =IFERROR('Historical Financial Statement '!F6/'Historical Financial Statement '!F54,0) -> 8.3372216 | G30: =IFERROR('Historical Financial Statement '!G6/'Historical Financial Statement '!G54,0) -> 7.2609965 | H30: =IFERROR('Historical Financial Statement '!H6/'Historical Financial Statement '!H54,0) -> 0.91417686 | I30: =IFERROR('Historical Financial Statement '!I6/'Historical Financial Statement '!I54,0) -> 1.0189031 | J30: =IFERROR('Historical Financial Statement '!J6/'Historical Financial Statement '!J54,0) -> 1.1500057 | ... L30: =IFERROR('Historical Financial Statement '!L6/'Historical Financial Statement '!L54,0) -> 1.1617006 | N30: =IFERROR(AVERAGE(C30:L30),0) -> 4.622821 | O30: =IFERROR(MEDIAN(C30:L30),0) -> 4.2113485
B31: Capital Turnover Ratio | C31: =IFERROR('Historical Financial Statement '!C6/SUM('Historical Financial Statement '!C48:C49),0) -> 4.8966986 | D31: =IFERROR('Historical Financial Statement '!D6/SUM('Historical Financial Statement '!D48:D49),0) -> 4.9172598 | E31: =IFERROR('Historical Financial Statement '!E6/SUM('Historical Financial Statement '!E48:E49),0) -> 4.8818844 | F31: =IFERROR('Historical Financial Statement '!F6/SUM('Historical Financial Statement '!F48:F49),0) -> 4.9968222 | G31: =IFERROR('Historical Financial Statement '!G6/SUM('Historical Financial Statement '!G48:G49),0) -> 4.8344878 | H31: =IFERROR('Historical Financial Statement '!H6/SUM('Historical Financial Statement '!H48:H49),0) -> 0.98644964 | I31: =IFERROR('Historical Financial Statement '!I6/SUM('Historical Financial Statement '!I48:I49),0) -> 1.0689957 | J31: =IFERROR('Historical Financial Statement '!J6/SUM('Historical Financial Statement '!J48:J49),0) -> 1.204278 | ... L31: =IFERROR('Historical Financial Statement '!L6/SUM('Historical Financial Statement '!L48:L49),0) -> 1.2777013 | N31: =IFERROR(AVERAGE(C31:L31),0) -> 3.0273059 | O31: =IFERROR(MEDIAN(C31:L31),0) -> 3.0560945
B33: Debtor Days | C33: =IFERROR(365/'Ratio Analysis'!C27,0) -> 14.334183 | D33: =IFERROR(365/'Ratio Analysis'!D27,0) -> 11.942133 | E33: =IFERROR(365/'Ratio Analysis'!E27,0) -> 13.451962 | F33: =IFERROR(365/'Ratio Analysis'!F27,0) -> 16.861867 | G33: =IFERROR(365/'Ratio Analysis'!G27,0) -> 10.541814 | H33: =IFERROR(365/'Ratio Analysis'!H27,0) -> 13.644425 | I33: =IFERROR(365/'Ratio Analysis'!I27,0) -> 15.56153 | J33: =IFERROR(365/'Ratio Analysis'!J27,0) -> 18.551255 | ... L33: =IFERROR(365/'Ratio Analysis'!L27,0) -> 22.083538 | N33: =IFERROR(AVERAGE(C33:L33),0) -> 15.464598 | O33: =IFERROR(MEDIAN(C33:L33),0) -> 14.947856
B34: Payable Days | C34: =IFERROR(365/C28,0) -> 91.210309 | D34: =IFERROR(365/D28,0) -> 95.592093 | E34: =IFERROR(365/E28,0) -> 108.65283 | F34: =IFERROR(365/F28,0) -> 99.007759 | G34: =IFERROR(365/G28,0) -> 109.39999 | H34: =IFERROR(365/H28,0) -> 163.50026 | I34: =IFERROR(365/I28,0) -> 141.98852 | J34: =IFERROR(365/J28,0) -> 129.86481 | ... L34: =IFERROR(365/L28,0) -> 166.61246 | N34: =IFERROR(AVERAGE(C34:L34),0) -> 125.78947 | O34: =IFERROR(MEDIAN(C34:L34),0) -> 119.6324
B35: Inventory Days | C35: =IFERROR(365/C29,0) -> 30.913751 | D35: =IFERROR(365/D29,0) -> 27.967704 | E35: =IFERROR(365/E29,0) -> 25.805177 | F35: =IFERROR(365/F29,0) -> 23.900025 | G35: =IFERROR(365/G29,0) -> 25.386597 | H35: =IFERROR(365/H29,0) -> 27.777813 | I35: =IFERROR(365/I29,0) -> 28.506273 | J35: =IFERROR(365/J29,0) -> 25.612661 | ... L35: =IFERROR(365/L29,0) -> 25.529935 | N35: =IFERROR(AVERAGE(C35:L35),0) -> 26.511762 | O35: =IFERROR(MEDIAN(C35:L35),0) -> 25.708919
B36: Cash Conversion Cycle | C36: =IFERROR(SUM(C33,C35)-C34,0) -> -45.962375 | D36: =IFERROR(SUM(D33,D35)-D34,0) -> -55.682257 | E36: =IFERROR(SUM(E33,E35)-E34,0) -> -69.395696 | F36: =IFERROR(SUM(F33,F35)-F34,0) -> -58.245866 | G36: =IFERROR(SUM(G33,G35)-G34,0) -> -73.471583 | H36: =IFERROR(SUM(H33,H35)-H34,0) -> -122.07802 | I36: =IFERROR(SUM(I33,I35)-I34,0) -> -97.920718 | J36: =IFERROR(SUM(J33,J35)-J34,0) -> -85.700891 | ... L36: =IFERROR(SUM(L33,L35)-L34,0) -> -118.99899 | N36: =IFERROR(AVERAGE(C36:L36),0) -> -83.813107 | O36: =IFERROR(MEDIAN(C36:L36),0) -> -79.586237
B38: CFO/Sales | C38: =IFERROR('Historical Financial Statement '!C83/'Historical Financial Statement '!C6,0) -> 0.12707388 | D38: =IFERROR('Historical Financial Statement '!D83/'Historical Financial Statement '!D6,0) -> 0.17342139 | E38: =IFERROR('Historical Financial Statement '!E83/'Historical Financial Statement '!E6,0) -> 0.19397946 | F38: =IFERROR('Historical Financial Statement '!F83/'Historical Financial Statement '!F6,0) -> 0.13884508 | G38: =IFERROR('Historical Financial Statement '!G83/'Historical Financial Statement '!G6,0) -> 0.20194555 | H38: =IFERROR('Historical Financial Statement '!H83/'Historical Financial Statement '!H6,0) -> 0.19269371 | I38: =IFERROR('Historical Financial Statement '!I83/'Historical Financial Statement '!I6,0) -> 0.15345308 | J38: =IFERROR('Historical Financial Statement '!J83/'Historical Financial Statement '!J6,0) -> 0.1490756 | ... L38: =IFERROR('Historical Financial Statement '!L83/'Historical Financial Statement '!L6,0) -> 0.17582104 | N38: =IFERROR(AVERAGE(C38:L38),0) -> 0.1777441 | O38: =IFERROR(MEDIAN(C38:L38),0) -> 0.17462121
B39: CFO/Total Assets | C39: =IFERROR('Historical Financial Statement '!C83/'Historical Financial Statement '!C65,0) -> 0.27648212 | D39: =IFERROR('Historical Financial Statement '!D83/'Historical Financial Statement '!D65,0) -> 0.3661658 | E39: =IFERROR('Historical Financial Statement '!E83/'Historical Financial Statement '!E65,0) -> 0.386015 | F39: =IFERROR('Historical Financial Statement '!F83/'Historical Financial Statement '!F65,0) -> 0.29298406 | G39: =IFERROR('Historical Financial Statement '!G83/'Historical Financial Statement '!G65,0) -> 0.39865033 | H39: =IFERROR('Historical Financial Statement '!H83/'Historical Financial Statement '!H65,0) -> 0.13183008 | I39: =IFERROR('Historical Financial Statement '!I83/'Historical Financial Statement '!I65,0) -> 0.11414631 | J39: =IFERROR('Historical Financial Statement '!J83/'Historical Financial Statement '!J65,0) -> 0.12358198 | ... L39: =IFERROR('Historical Financial Statement '!L83/'Historical Financial Statement '!L65,0) -> 0.13896297 | N39: =IFERROR(AVERAGE(C39:L39),0) -> 0.24426321 | O39: =IFERROR(MEDIAN(C39:L39),0) -> 0.24514776
B40: CFO/Total Debt | C40: =IFERROR('Historical Financial Statement '!C83/'Historical Financial Statement '!C50,0) -> 23.107345 | D40: =IFERROR('Historical Financial Statement '!D83/'Historical Financial Statement '!D50,0) -> 20.761733 | E40: =IFERROR('Historical Financial Statement '!E83/'Historical Financial Statement '!E50,0) -> 0 | F40: =IFERROR('Historical Financial Statement '!F83/'Historical Financial Statement '!F50,0) -> 55.131313 | G40: =IFERROR('Historical Financial Statement '!G83/'Historical Financial Statement '!G50,0) -> 0 | H40: =IFERROR('Historical Financial Statement '!H83/'Historical Financial Statement '!H50,0) -> 0 | I40: =IFERROR('Historical Financial Statement '!I83/'Historical Financial Statement '!I50,0) -> 7.7162033 | J40: =IFERROR('Historical Financial Statement '!J83/'Historical Financial Statement '!J50,0) -> 7.4085316 | ... L40: =IFERROR('Historical Financial Statement '!L83/'Historical Financial Statement '!L50,0) -> 6.7342233 | N40: =IFERROR(AVERAGE(C40:L40),0) -> 13.216797 | O40: =IFERROR(MEDIAN(C40:L40),0) -> 7.5623674

Sheet Historical Financial Statement 
B2: ="Historical Financial Statement - "&'Data Sheet'!B1 -> Historical Financial Statement - HINDUSTAN UNILEVER LTD
B3: Years | C3: ='Data Sheet'!B16 -> 42460 | D3: ='Data Sheet'!C16 -> 42825 | E3: ='Data Sheet'!D16 -> 43190 | F3: ='Data Sheet'!E16 -> 43555 | G3: ='Data Sheet'!F16 -> 43921 | H3: ='Data Sheet'!G16 -> 44286 | I3: ='Data Sheet'!H16 -> 44651 | J3: ='Data Sheet'!I16 -> 45016 | ... L3: ='Data Sheet'!K16 -> 45747 | M3: LTM
A5: # | B5: Income Statement
B6: Sales | C6: =IFERROR('Data Sheet'!B17,0) -> 32186 | D6: =IFERROR('Data Sheet'!C17,0) -> 33162 | E6: =IFERROR('Data Sheet'!D17,0) -> 35545 | F6: =IFERROR('Data Sheet'!E17,0) -> 39310 | G6: =IFERROR('Data Sheet'!F17,0) -> 39783 | H6: =IFERROR('Data Sheet'!G17,0) -> 47028 | I6: =IFERROR('Data Sheet'!H17,0) -> 52446 | J6: =IFERROR('Data Sheet'!I17,0) -> 60580 | ... L6: =IFERROR('Data Sheet'!K17,0) -> 63121 | M6: =IFERROR(SUM('Data Sheet'!H42:K42),0) -> 64243
B7: Sales Growth | C7: - | D7: =D6/C6-1 -> 0.030323743 | E7: =E6/D6-1 -> 0.071859357 | F7: =F6/E6-1 -> 0.10592207 | G7: =G6/F6-1 -> 0.012032562 | H7: =H6/G6-1 -> 0.18211296 | I7: =I6/H6-1 -> 0.11520796 | J7: =J6/I6-1 -> 0.15509286 | K7: =K6/J6-1 -> 0.021723341 | ... M7: =M6/L6-1 -> 0.017775384
B9: COGS | C9: =IFERROR(SUM('Data Sheet'!B18,'Data Sheet'!B20,'Data Sheet'!B21,'Data Sheet'!B22)-1*'Data Sheet'!B19,0) -> 18222 | D9: =IFERROR(SUM('Data Sheet'!C18,'Data Sheet'!C20,'Data Sheet'!C21,'Data Sheet'!C22)-1*'Data Sheet'!C19,0) -> 18675 | E9: =IFERROR(SUM('Data Sheet'!D18,'Data Sheet'!D20,'Data Sheet'!D21,'Data Sheet'!D22)-1*'Data Sheet'!D19,0) -> 19314 | F9: =IFERROR(SUM('Data Sheet'!E18,'Data Sheet'!E20,'Data Sheet'!E21,'Data Sheet'!E22)-1*'Data Sheet'!E19,0) -> 21081 | G9: =IFERROR(SUM('Data Sheet'!F18,'Data Sheet'!F20,'Data Sheet'!F21,'Data Sheet'!F22)-1*'Data Sheet'!F19,0) -> 20614 | H9: =IFERROR(SUM('Data Sheet'!G18,'Data Sheet'!G20,'Data Sheet'!G21,'Data Sheet'!G22)-1*'Data Sheet'!G19,0) -> 25301 | I9: =IFERROR(SUM('Data Sheet'!H18,'Data Sheet'!H20,'Data Sheet'!H21,'Data Sheet'!H22)-1*'Data Sheet'!H19,0) -> 29066 | J9: =IFERROR(SUM('Data Sheet'!I18,'Data Sheet'!I20,'Data Sheet'!I21,'Data Sheet'!I22)-1*'Data Sheet'!I19,0) -> 35381 | ... L9: =IFERROR(SUM('Data Sheet'!K18,'Data Sheet'!K20,'Data Sheet'!K21,'Data Sheet'!K22)-1*'Data Sheet'!K19,0) -> 34529 | M9: =IFERROR(SUM('Data Sheet'!H43:K43),0) -> 49487
B10: COGS % Sales | C10: =C9/C6 -> 0.56614677 | D10: =D9/D6 -> 0.56314456 | E10: =E9/E6 -> 0.54336756 | F10: =F9/F6 -> 0.53627576 | G10: =G9/G6 -> 0.51816102 | H10: =H9/H6 -> 0.53799864 | I10: =I9/I6 -> 0.55420814 | J10: =J9/J6 -> 0.58403764 | ... M10: =M9/M6 -> 0.77030961
B12: Gross Profit | C12: =C6-C9 -> 13964 | D12: =D6-D9 -> 14487 | E12: =E6-E9 -> 16231 | F12: =F6-F9 -> 18229 | G12: =G6-G9 -> 19169 | H12: =H6-H9 -> 21727 | I12: =I6-I9 -> 23380 | J12: =J6-J9 -> 25199 | ... M12: =M6-M9 -> 14756
B13: Gross Profit Margins | C13: =C12/C6 -> 0.43385323 | D13: =D12/D6 -> 0.43685544 | E13: =E12/E6 -> 0.45663244 | F13: =F12/F6 -> 0.46372424 | G13: =G12/G6 -> 0.48183898 | H13: =H12/H6 -> 0.46200136 | I13: =I12/I6 -> 0.44579186 | J13: =J12/J6 -> 0.41596236 | ... M13: =M12/M6 -> 0.22969039
B15: Selling & General Expenses | C15: =IFERROR(SUM('Data Sheet'!B23:B24),0) -> 8054 | D15: =IFERROR(SUM('Data Sheet'!C23:C24),0) -> 8159 | E15: =IFERROR(SUM('Data Sheet'!D23:D24),0) -> 8732 | F15: =IFERROR(SUM('Data Sheet'!E23:E24),0) -> 9349 | G15: =IFERROR(SUM('Data Sheet'!F23:F24),0) -> 9308 | H15: =IFERROR(SUM('Data Sheet'!G23:G24),0) -> 10101 | I15: =IFERROR(SUM('Data Sheet'!H23:H24),0) -> 10523 | J15: =IFERROR(SUM('Data Sheet'!I23:I24),0) -> 11052 | ... M15: =IFERROR(SUM('Data Sheet'!L23:L24),0) -> 0
B16: SG&A Exp as a% of Sales | C16: =C15/C6 -> 0.25023302 | D16: =D15/D6 -> 0.24603462 | E16: =E15/E6 -> 0.24566043 | F16: =F15/F6 -> 0.23782752 | G16: =G15/G6 -> 0.23396928 | H16: =H15/H6 -> 0.21478694 | I16: =I15/I6 -> 0.20064447 | J16: =J15/J6 -> 0.18243645 | ... M16: =M15/M6 -> 0
B18: EBITDA | C18: =C12-C15 -> 5910 | D18: =D12-D15 -> 6328 | E18: =E12-E15 -> 7499 | F18: =F12-F15 -> 8880 | G18: =G12-G15 -> 9861 | H18: =H12-H15 -> 11626 | I18: =I12-I15 -> 12857 | J18: =J12-J15 -> 14147 | ... M18: =M12-M15 -> 14756
B19: EBITDA Margins | C19: =C18/C6 -> 0.18362021 | D19: =D18/D6 -> 0.19082082 | E19: =E18/E6 -> 0.21097201 | F19: =F18/F6 -> 0.22589672 | G19: =G18/G6 -> 0.24786969 | H19: =H18/H6 -> 0.24721443 | I19: =I18/I6 -> 0.24514739 | J19: =J18/J6 -> 0.23352592 | ... M19: =M18/M6 -> 0.22969039
B21: Interest | C21: =IFERROR('Data Sheet'!B27,0) -> 17 | D21: =IFERROR('Data Sheet'!C27,0) -> 35 | E21: =IFERROR('Data Sheet'!D27,0) -> 26 | F21: =IFERROR('Data Sheet'!E27,0) -> 33 | G21: =IFERROR('Data Sheet'!F27,0) -> 118 | H21: =IFERROR('Data Sheet'!G27,0) -> 117 | I21: =IFERROR('Data Sheet'!H27,0) -> 106 | J21: =IFERROR('Data Sheet'!I27,0) -> 114 | ... L21: =IFERROR('Data Sheet'!K27,0) -> 395 | M21: =IFERROR(SUM('Data Sheet'!H46:K46),0) -> 448
B22: Interest as a % of Sales | C22: =C21/C6 -> 0.00052817995 | D22: =D21/D6 -> 0.0010554249 | E22: =E21/E6 -> 0.00073146715 | F22: =F21/F6 -> 0.00083948105 | G22: =G21/G6 -> 0.002966091 | H22: =H21/H6 -> 0.0024878796 | I22: =I21/I6 -> 0.0020211265 | J22: =J21/J6 -> 0.0018818092 | ... M22: =M21/M6 -> 0.0069735224
B24: Depreciation | C24: =IFERROR('Data Sheet'!B26,0) -> 353 | D24: =IFERROR('Data Sheet'!C26,0) -> 432 | E24: =IFERROR('Data Sheet'!D26,0) -> 520 | F24: =IFERROR('Data Sheet'!E26,0) -> 565 | G24: =IFERROR('Data Sheet'!F26,0) -> 1002 | H24: =IFERROR('Data Sheet'!G26,0) -> 1074 | I24: =IFERROR('Data Sheet'!H26,0) -> 1091 | J24: =IFERROR('Data Sheet'!I26,0) -> 1137 | ... L24: =IFERROR('Data Sheet'!K26,0) -> 1355 | M24: =IFERROR(SUM('Data Sheet'!H45:K45),0) -> 1407
B25: Depreciation as a % of Sales | C25: =C24/C6 -> 0.010967501 | D25: =D24/D6 -> 0.013026959 | E25: =E24/E6 -> 0.014629343 | F25: =F24/F6 -> 0.014372933 | G25: =G24/G6 -> 0.025186638 | H25: =H24/H6 -> 0.022837459 | I25: =I24/I6 -> 0.020802349 | J25: =J24/J6 -> 0.01876857 | ... M25: =M24/M6 -> 0.021901219
B27: EBT | C27: =IFERROR(C18-SUM(C21,C24),0) -> 5540 | D27: =IFERROR(D18-SUM(D21,D24),0) -> 5861 | E27: =IFERROR(E18-SUM(E21,E24),0) -> 6953 | F27: =IFERROR(F18-SUM(F21,F24),0) -> 8282 | G27: =IFERROR(G18-SUM(G21,G24),0) -> 8741 | H27: =IFERROR(H18-SUM(H21,H24),0) -> 10435 | I27: =IFERROR(I18-SUM(I21,I24),0) -> 11660 | J27: =IFERROR(J18-SUM(J21,J24),0) -> 12896 | ... M27: =IFERROR(M18-SUM(M21,M24),0) -> 12901
B28: EBT % of Sales | C28: =C27/C6 -> 0.17212453 | D28: =D27/D6 -> 0.17673844 | E28: =E27/E6 -> 0.1956112 | F28: =F27/F6 -> 0.2106843 | G28: =G27/G6 -> 0.21971696 | H28: =H27/H6 -> 0.22188909 | I28: =I27/I6 -> 0.22232391 | J28: =J27/J6 -> 0.21287554 | ... M28: =M27/M6 -> 0.20081565
B30: Tax | C30: =IFERROR('Data Sheet'!B29,0) -> 1875 | D30: =IFERROR('Data Sheet'!C29,0) -> 1977 | E30: =IFERROR('Data Sheet'!D29,0) -> 2079 | F30: =IFERROR('Data Sheet'!E29,0) -> 2544 | G30: =IFERROR('Data Sheet'!F29,0) -> 2409 | H30: =IFERROR('Data Sheet'!G29,0) -> 2606 | I30: =IFERROR('Data Sheet'!H29,0) -> 2987 | J30: =IFERROR('Data Sheet'!I29,0) -> 3201 | ... L30: =IFERROR('Data Sheet'!K29,0) -> 3744 | M30: =IFERROR(SUM('Data Sheet'!H48:K48),0) -> 3291
B31: Effective Tax Rate | C31: =C30/C27 -> 0.33844765 | D31: =D30/D27 -> 0.33731445 | E31: =E30/E27 -> 0.29900762 | F31: =F30/F27 -> 0.30717218 | G31: =G30/G27 -> 0.27559776 | H31: =H30/H27 -> 0.24973646 | I31: =I30/I27 -> 0.25617496 | J31: =J30/J27 -> 0.2482165 | ... M31: =M30/M27 -> 0.2550965
B33: Net Profit | C33: =IFERROR(C27-C30,0) -> 3665 | D33: =IFERROR(D27-D30,0) -> 3884 | E33: =IFERROR(E27-E30,0) -> 4874 | F33: =IFERROR(F27-F30,0) -> 5738 | G33: =IFERROR(G27-G30,0) -> 6332 | H33: =IFERROR(H27-H30,0) -> 7829 | I33: =IFERROR(I27-I30,0) -> 8673 | J33: =IFERROR(J27-J30,0) -> 9695 | ... L33: =IFERROR(L27-L30,0) -> 9349 | M33: =IFERROR(SUM('Data Sheet'!H49:K49),0) -> 10889
B34: Net Margins | C34: =IFERROR(C33/C6,0) -> 0.11386938 | D34: =IFERROR(D33/D6,0) -> 0.11712201 | E34: =IFERROR(E33/E6,0) -> 0.13712196 | F34: =IFERROR(F33/F6,0) -> 0.14596795 | G34: =IFERROR(G33/G6,0) -> 0.15916346 | H34: =IFERROR(H33/H6,0) -> 0.16647529 | I34: =IFERROR(I33/I6,0) -> 0.16537009 | J34: =IFERROR(J33/J6,0) -> 0.16003632 | ... M34: =IFERROR(M33/M6,0) -> 0.16949707
B36: No of Equity Shares | C36: =IFERROR('Data Sheet'!B93,0) -> 216.39 | D36: =IFERROR('Data Sheet'!C93,0) -> 216.43 | E36: =IFERROR('Data Sheet'!D93,0) -> 216.45 | F36: =IFERROR('Data Sheet'!E93,0) -> 216.47 | G36: =IFERROR('Data Sheet'!F93,0) -> 216.48 | H36: =IFERROR('Data Sheet'!G93,0) -> 234.96 | I36: =IFERROR('Data Sheet'!H93,0) -> 234.96 | J36: =IFERROR('Data Sheet'!I93,0) -> 234.96 | ... M36: =IFERROR('Data Sheet'!L93,0) -> 0
B38: Earnings Per Share | C38: =IFERROR(C33/C36,0) -> 16.937012 | D38: =IFERROR(D33/D36,0) -> 17.945756 | E38: =IFERROR(E33/E36,0) -> 22.517903 | F38: =IFERROR(F33/F36,0) -> 26.507137 | G38: =IFERROR(G33/G36,0) -> 29.249815 | H38: =IFERROR(H33/H36,0) -> 33.320565 | I38: =IFERROR(I33/I36,0) -> 36.912666 | J38: =IFERROR(J33/J36,0) -> 41.262343 | ... M38: =IFERROR(M33/M36,0) -> 0
B39: EPS Growth % | D39: =IFERROR(D38/C38-1,0) -> 0.059558573 | E39: =IFERROR(E38/D38-1,0) -> 0.25477591 | F39: =IFERROR(F38/E38-1,0) -> 0.17715836 | G39: =IFERROR(G38/F38-1,0) -> 0.10346941 | H39: =IFERROR(H38/G38-1,0) -> 0.13917182 | I39: =IFERROR(I38/H38-1,0) -> 0.10780432 | J39: =IFERROR(J38/I38-1,0) -> 0.11783697 | K39: =IFERROR(K38/J38-1,0) -> -0.023723569 | ... M39: =IFERROR(M38/L38-1,0) -> -1
B41: Dividend Per Share | C41: =IFERROR('Data Sheet'!B31/C36,0) -> 15.971163 | D41: =IFERROR('Data Sheet'!C31/D36,0) -> 16.966225 | E41: =IFERROR('Data Sheet'!D31/E36,0) -> 19.95842 | F41: =IFERROR('Data Sheet'!E31/F36,0) -> 21.952234 | G41: =IFERROR('Data Sheet'!F31/G36,0) -> 24.944568 | H41: =IFERROR('Data Sheet'!G31/H36,0) -> 40.506895 | I41: =IFERROR('Data Sheet'!H31/I36,0) -> 34.005788 | J41: =IFERROR('Data Sheet'!I31/J36,0) -> 39.006639 | ... M41: =IFERROR('Data Sheet'!L31/M36,0) -> 0
B42: Dividend Payout Ratio | C42: =IFERROR(C41/C38,0) -> 0.94297408 | D42: =IFERROR(D41/D38,0) -> 0.9454171 | E42: =IFERROR(E41/E38,0) -> 0.88633566 | F42: =IFERROR(F41/F38,0) -> 0.82816312 | G42: =IFERROR(G41/G38,0) -> 0.85281112 | H42: =IFERROR(H41/H38,0) -> 1.2156725 | I42: =IFERROR(I41/I38,0) -> 0.92124986 | J42: =IFERROR(J41/J38,0) -> 0.94533265 | ... M42: =IFERROR(M41/M38,0) -> 0
B44: Retained Earnings | C44: =IFERROR(IF(C38>C41,1-C42,0),0) -> 0.057025921 | D44: =IFERROR(IF(D38>D41,1-D42,0),0) -> 0.054582904 | E44: =IFERROR(IF(E38>E41,1-E42,0),0) -> 0.11366434 | F44: =IFERROR(IF(F38>F41,1-F42,0),0) -> 0.17183688 | G44: =IFERROR(IF(G38>G41,1-G42,0),0) -> 0.14718888 | H44: =IFERROR(IF(H38>H41,1-H42,0),0) -> 0 | I44: =IFERROR(IF(I38>I41,1-I42,0),0) -> 0.078750144 | J44: =IFERROR(IF(J38>J41,1-J42,0),0) -> 0.054667354 | ... M44: =IFERROR(IF(M38>M41,1-M42,0),0) -> 0
A47: # | B47: Balance Sheet
B48: Equity Share Capital | C48: =IFERROR('Data Sheet'!B57,0) -> 216 | D48: =IFERROR('Data Sheet'!C57,0) -> 216 | E48: =IFERROR('Data Sheet'!D57,0) -> 216 | F48: =IFERROR('Data Sheet'!E57,0) -> 216 | G48: =IFERROR('Data Sheet'!F57,0) -> 216 | H48: =IFERROR('Data Sheet'!G57,0) -> 235 | I48: =IFERROR('Data Sheet'!H57,0) -> 235 | J48: =IFERROR('Data Sheet'!I57,0) -> 235 | ... M48: =IFERROR('Data Sheet'!L57,0) -> 0
B49: Reserves | C49: =IFERROR('Data Sheet'!B58,0) -> 6357 | D49: =IFERROR('Data Sheet'!C58,0) -> 6528 | E49: =IFERROR('Data Sheet'!D58,0) -> 7065 | F49: =IFERROR('Data Sheet'!E58,0) -> 7651 | G49: =IFERROR('Data Sheet'!F58,0) -> 8013 | H49: =IFERROR('Data Sheet'!G58,0) -> 47439 | I49: =IFERROR('Data Sheet'!H58,0) -> 48826 | J49: =IFERROR('Data Sheet'!I58,0) -> 50069 | ... M49: =IFERROR('Data Sheet'!L58,0) -> 0
B50: Borrowings | C50: =IFERROR('Data Sheet'!B59,0) -> 177 | D50: =IFERROR('Data Sheet'!C59,0) -> 277 | E50: =IFERROR('Data Sheet'!D59,0) -> 0 | F50: =IFERROR('Data Sheet'!E59,0) -> 99 | G50: =IFERROR('Data Sheet'!F59,0) -> 0 | H50: =IFERROR('Data Sheet'!G59,0) -> 0 | I50: =IFERROR('Data Sheet'!H59,0) -> 1043 | J50: =IFERROR('Data Sheet'!I59,0) -> 1219 | ... M50: =IFERROR('Data Sheet'!L59,0) -> 0
B51: Other Liabilities | C51: =IFERROR('Data Sheet'!B60,0) -> 8043 | D51: =IFERROR('Data Sheet'!C60,0) -> 8685 | E51: =IFERROR('Data Sheet'!D60,0) -> 10581 | F51: =IFERROR('Data Sheet'!E60,0) -> 10663 | G51: =IFERROR('Data Sheet'!F60,0) -> 11924 | H51: =IFERROR('Data Sheet'!G60,0) -> 21066 | I51: =IFERROR('Data Sheet'!H60,0) -> 20402 | J51: =IFERROR('Data Sheet'!I60,0) -> 21554 | ... M51: =IFERROR('Data Sheet'!L60,0) -> 0
B52: Total Liabilities | C52: =IFERROR('Data Sheet'!B61,0) -> 14793 | D52: =IFERROR('Data Sheet'!C61,0) -> 15706 | E52: =IFERROR('Data Sheet'!D61,0) -> 17862 | F52: =IFERROR('Data Sheet'!E61,0) -> 18629 | G52: =IFERROR('Data Sheet'!F61,0) -> 20153 | H52: =IFERROR('Data Sheet'!G61,0) -> 68740 | I52: =IFERROR('Data Sheet'!H61,0) -> 70506 | J52: =IFERROR('Data Sheet'!I61,0) -> 73077 | ... M52: =IFERROR('Data Sheet'!L61,0) -> 0
B54: Fixed Assets Net Block | C54: =IFERROR('Data Sheet'!B62,0) -> 3258 | D54: =IFERROR('Data Sheet'!C62,0) -> 4419 | E54: =IFERROR('Data Sheet'!D62,0) -> 4528 | F54: =IFERROR('Data Sheet'!E62,0) -> 4715 | G54: =IFERROR('Data Sheet'!F62,0) -> 5479 | H54: =IFERROR('Data Sheet'!G62,0) -> 51443 | I54: =IFERROR('Data Sheet'!H62,0) -> 51473 | J54: =IFERROR('Data Sheet'!I62,0) -> 52678 | ... M54: =IFERROR('Data Sheet'!L62,0) -> 0
B55: Capital Work in Progress | C55: =IFERROR('Data Sheet'!B63,0) -> 408 | D55: =IFERROR('Data Sheet'!C63,0) -> 229 | E55: =IFERROR('Data Sheet'!D63,0) -> 461 | F55: =IFERROR('Data Sheet'!E63,0) -> 406 | G55: =IFERROR('Data Sheet'!F63,0) -> 597 | H55: =IFERROR('Data Sheet'!G63,0) -> 745 | I55: =IFERROR('Data Sheet'!H63,0) -> 1313 | J55: =IFERROR('Data Sheet'!I63,0) -> 1132 | ... M55: =IFERROR('Data Sheet'!L63,0) -> 0
B56: Investments | C56: =IFERROR('Data Sheet'!B64,0) -> 2592 | D56: =IFERROR('Data Sheet'!C64,0) -> 3794 | E56: =IFERROR('Data Sheet'!D64,0) -> 2873 | F56: =IFERROR('Data Sheet'!E64,0) -> 2716 | G56: =IFERROR('Data Sheet'!F64,0) -> 1255 | H56: =IFERROR('Data Sheet'!G64,0) -> 2709 | I56: =IFERROR('Data Sheet'!H64,0) -> 3521 | J56: =IFERROR('Data Sheet'!I64,0) -> 2882 | ... M56: =IFERROR('Data Sheet'!L64,0) -> 0
B57: Other Assets | C57: =IFERROR('Data Sheet'!B65-SUM('Data Sheet'!B67:B69),0) -> 1536 | D57: =IFERROR('Data Sheet'!C65-SUM('Data Sheet'!C67:C69),0) -> 1810 | E57: =IFERROR('Data Sheet'!D65-SUM('Data Sheet'!D67:D69),0) -> 2692 | F57: =IFERROR('Data Sheet'!E65-SUM('Data Sheet'!E67:E69),0) -> 2645 | G57: =IFERROR('Data Sheet'!F65-SUM('Data Sheet'!F67:F69),0) -> 3793 | H57: =IFERROR('Data Sheet'!G65-SUM('Data Sheet'!G67:G69),0) -> 4035 | I57: =IFERROR('Data Sheet'!H65-SUM('Data Sheet'!H67:H69),0) -> 4021 | J57: =IFERROR('Data Sheet'!I65-SUM('Data Sheet'!I67:I69),0) -> 4377 | ... M57: =IFERROR('Data Sheet'!L65-SUM('Data Sheet'!L67:L69),0) -> 0
B58: Total Non Current Assets | C58: =SUM(C54:C57) -> 7794 | D58: =SUM(D54:D57) -> 10252 | E58: =SUM(E54:E57) -> 10554 | F58: =SUM(F54:F57) -> 10482 | G58: =SUM(G54:G57) -> 11124 | H58: =SUM(H54:H57) -> 58932 | I58: =SUM(I54:I57) -> 60328 | J58: =SUM(J54:J57) -> 61069 | ... M58: =SUM(M54:M57) -> 0
...

Sheet Forecasting
B3: ='Data Sheet'!B1&" - "&'Data Sheet'!A17 -> HINDUSTAN UNILEVER LTD - Sales | G3: ='Data Sheet'!B1&" - "&'Historical Financial Statement '!B18&" Forecasting" -> HINDUSTAN UNILEVER LTD - EBITDA Forecasting | L3: ='Data Sheet'!B1&" - "&'Historical Financial Statement '!B38&" Forecasting" -> HINDUSTAN UNILEVER LTD - Earnings Per Share Forecasting
B4: Year Weight | C4: Year | D4: Sales | E4: Sales Growth | G4: Year Weight | H4: Year | I4: Sales | J4: Sales Growth | L4: Year Weight | M4: Year | N4: Sales | O4: Sales Growth
B5: 1 | C5: ='Data Sheet'!B16 -> 42460 | D5: {=TRANSPOSE('Data Sheet'!B17:K17)} -> 32186 | G5: 1 | H5: ='Data Sheet'!B16 -> 42460 | I5: {=TRANSPOSE('Historical Financial Statement '!C18:L18)} -> 5910 | L5: 1 | M5: ='Data Sheet'!G16 -> 44286 | N5: {=TRANSPOSE('Historical Financial Statement '!C38:L38)} -> 16.937012
B6: =B5+1 -> 2 | C6: =C5+365 -> 42825 | D6: 33162 | E6: =D6/D5-1 -> 0.030323743 | G6: =G5+1 -> 2 | H6: =H5+365 -> 42825 | I6: 6328 | J6: =I6/I5-1 -> 0.07072758 | L6: =L5+1 -> 2 | M6: =M5+365 -> 44651 | N6: 17.945756 | O6: =N6/N5-1 -> 0.059558573
B7: =B6+1 -> 3 | C7: =C6+365 -> 43190 | D7: 35545 | E7: =D7/D6-1 -> 0.071859357 | G7: =G6+1 -> 3 | H7: =H6+365 -> 43190 | I7: 7499 | J7: =I7/I6-1 -> 0.18505057 | L7: =L6+1 -> 3 | M7: =M6+365 -> 45016 | N7: 22.517903 | O7: =N7/N6-1 -> 0.25477591
B8: =B7+1 -> 4 | C8: =C7+365 -> 43555 | D8: 39310 | E8: =D8/D7-1 -> 0.10592207 | G8: =G7+1 -> 4 | H8: =H7+365 -> 43555 | I8: 8880 | J8: =I8/I7-1 -> 0.18415789 | L8: =L7+1 -> 4 | M8: =M7+365 -> 45381 | N8: 26.507137 | O8: =N8/N7-1 -> 0.17715836
B9: =B8+1 -> 5 | C9: =C8+365 -> 43920 | D9: 39783 | E9: =D9/D8-1 -> 0.012032562 | G9: =G8+1 -> 5 | H9: =H8+365 -> 43920 | I9: 9861 | J9: =I9/I8-1 -> 0.11047297 | L9: =L8+1 -> 5 | M9: =M8+365 -> 45746 | N9: 29.249815 | O9: =N9/N8-1 -> 0.10346941
B10: =B9+1 -> 6 | C10: =C9+365 -> 44285 | D10: 47028 | E10: =D10/D9-1 -> 0.18211296 | G10: =G9+1 -> 6 | H10: =H9+365 -> 44285 | I10: 11626 | J10: =I10/I9-1 -> 0.17898793 | L10: =L9+1 -> 6 | M10: =M9+365 -> 46111 | N10: 33.320565 | O10: =N10/N9-1 -> 0.13917182
B11: =B10+1 -> 7 | C11: =C10+365 -> 44650 | D11: 52446 | E11: =D11/D10-1 -> 0.11520796 | G11: =G10+1 -> 7 | H11: =H10+365 -> 44650 | I11: 12857 | J11: =I11/I10-1 -> 0.10588336 | L11: =L10+1 -> 7 | M11: =M10+365 -> 46476 | N11: 36.912666 | O11: =N11/N10-1 -> 0.10780432
B12: =B11+1 -> 8 | C12: =C11+365 -> 45015 | D12: 60580 | E12: =D12/D11-1 -> 0.15509286 | G12: =G11+1 -> 8 | H12: =H11+365 -> 45015 | I12: 14147 | J12: =I12/I11-1 -> 0.10033445 | L12: =L11+1 -> 8 | M12: =M11+365 -> 46841 | N12: 41.262343 | O12: =N12/N11-1 -> 0.11783697
B13: =B12+1 -> 9 | C13: =C12+365 -> 45380 | D13: 61896 | E13: =D13/D12-1 -> 0.021723341 | G13: =G12+1 -> 9 | H13: =H12+365 -> 45380 | I13: 14659 | J13: =I13/I12-1 -> 0.036191419 | L13: =L12+1 -> 9 | M13: =M12+365 -> 47206 | N13: 40.283453 | O13: =N13/N12-1 -> -0.023723569
B14: =B13+1 -> 10 | C14: =C13+365 -> 45745 | D14: 63121 | E14: =D14/D13-1 -> 0.019791263 | G14: =G13+1 -> 10 | H14: =H13+365 -> 45745 | I14: 14843 | J14: =I14/I13-1 -> 0.012552016 | L14: =L13+1 -> 10 | M14: =M13+365 -> 47571 | N14: 39.789751 | O14: =N14/N13-1 -> -0.012255679
B15: =B14+1 -> 11 | C15: =C14+365 -> 46110 | D15: =FORECAST(B15,$D$5:$D$14,$B$5:$B$14) -> 68218.4 | E15: =D15/D14-1 -> 0.080756008 | G15: =G14+1 -> 11 | H15: =H14+365 -> 46110 | I15: =FORECAST(G15,$I$5:$I$14,$G$5:$G$14) -> 16849.333 | J15: =I15/I14-1 -> 0.13517034 | L15: =L14+1 -> 11 | M15: =M14+365 -> 47936 | N15: =FORECAST(L15,$N$5:$N$14,$L$5:$L$14) -> 46.840909 | O15: =N15/N14-1 -> 0.17721039
B16: =B15+1 -> 12 | C16: =C15+365 -> 46475 | D16: =FORECAST(B16,$D$5:$D$14,$B$5:$B$14) -> 72166.164 | E16: =D16/D15-1 -> 0.057869484 | G16: =G15+1 -> 12 | H16: =H15+365 -> 46475 | I16: =FORECAST(G16,$I$5:$I$14,$G$5:$G$14) -> 17974.485 | J16: =I16/I15-1 -> 0.066777213 | L16: =L15+1 -> 12 | M16: =M15+365 -> 48301 | N16: =FORECAST(L16,$N$5:$N$14,$L$5:$L$14) -> 49.816958 | O16: =N16/N15-1 -> 0.063535251
B17: =B16+1 -> 13 | C17: =C16+365 -> 46840 | D17: =FORECAST(B17,$D$5:$D$14,$B$5:$B$14) -> 76113.927 | E17: =D17/D16-1 -> 0.054703804 | G17: =G16+1 -> 13 | H17: =H16+365 -> 46840 | I17: =FORECAST(G17,$I$5:$I$14,$G$5:$G$14) -> 19099.636 | J17: =I17/I16-1 -> 0.062597149 | L17: =L16+1 -> 13 | M17: =M16+365 -> 48666 | N17: =FORECAST(L17,$N$5:$N$14,$L$5:$L$14) -> 52.793007 | O17: =N17/N16-1 -> 0.059739675
B18: =B17+1 -> 14 | C18: =C17+365 -> 47205 | D18: =FORECAST(B18,$D$5:$D$14,$B$5:$B$14) -> 80061.691 | E18: =D18/D17-1 -> 0.051866508 | G18: =G17+1 -> 14 | H18: =H17+365 -> 47205 | I18: =FORECAST(G18,$I$5:$I$14,$G$5:$G$14) -> 20224.788 | J18: =I18/I17-1 -> 0.058909578 | L18: =L17+1 -> 14 | M18: =M17+365 -> 49031 | N18: =FORECAST(L18,$N$5:$N$14,$L$5:$L$14) -> 55.769056 | O18: =N18/N17-1 -> 0.056372029
B19: =B18+1 -> 15 | C19: =C18+365 -> 47570 | D19: =FORECAST(B19,$D$5:$D$14,$B$5:$B$14) -> 84009.455 | E19: =D19/D18-1 -> 0.049309021 | G19: =G18+1 -> 15 | H19: =H18+365 -> 47570 | I19: =FORECAST(G19,$I$5:$I$14,$G$5:$G$14) -> 21349.939 | J19: =I19/I18-1 -> 0.055632302 | L19: =L18+1 -> 15 | M19: =M18+365 -> 49396 | N19: =FORECAST(L19,$N$5:$N$14,$L$5:$L$14) -> 58.745105 | O19: =N19/N18-1 -> 0.053363803

Sheet Cash Flow Data 
C2: 42430 | D2: 42795 | E2: 43160 | F2: 43525 | G2: 43891 | H2: 44256 | I2: 44621 | J2: 44986 | K2: 45352 | L2: 45717
B3: Cash from Operating Activity - | C3: 4171 | D3: 5185 | E3: 6059 | F3: 5800 | G3: 7623 | H3: 9163 | I3: 9048 | J3: 9991 | K3: 15469 | L3: 11886
B4: Profit from operations | C4: 6025 | D4: 6512 | E4: 7485 | F4: 8909 | G4: 9723 | H4: 11672 | I4: 12829 | J4: 14089 | K4: 14537 | L4: 14942
B5: Receivables | C5: -257 | D5: 173 | E5: 0 | F5: 0 | G5: 0 | H5: 0 | I5: 0 | J5: 0 | K5: 0 | L5: 0
B6: Inventory | C6: 89 | D6: 37 | E6: -146 | F6: -195 | G6: -331 | H6: -543 | I6: -758 | J6: -339 | K6: 74 | L6: -584
B7: Payables | C7: 164 | D7: 501 | E7: 0 | F7: 0 | G7: 0 | H7: 0 | I7: 0 | J7: 0 | K7: 0 | L7: 0
B8: Loans Advances | C8: 0 | D8: 0 | E8: 0 | F8: 0 | G8: 0 | H8: 0 | I8: 0 | J8: 0 | K8: 0 | L8: 0
B9: Operating Deposits | C9: 0 | D9: -46 | E9: 0 | F9: 0 | G9: 0 | H9: 0 | I9: 0 | J9: 0 | K9: 0 | L9: 0
B10: Other WC items | C10: -77 | D10: -99 | E10: 982 | F10: -147 | G10: 742 | H10: 442 | I10: -242 | J10: -621 | K10: 1239 | L10: -204
B11: Working capital changes | C11: -81 | D11: 566 | E11: 836 | F11: -342 | G11: 411 | H11: -101 | I11: -1000 | J11: -960 | K11: 1313 | L11: -788
B12: Direct taxes | C12: -1765 | D12: -1859 | E12: -2264 | F12: -2767 | G12: -2505 | H12: -2407 | I12: -2784 | J12: -3138 | K12: -381 | L12: -2268
B13: Other operating items | C13: -8 | D13: -21 | E13: 0 | F13: 0 | G13: 0 | H13: 0 | I13: 0 | J13: 0 | K13: 0 | L13: 0
B14: Exceptional CF items | C14: 0 | D14: -13 | E14: 2 | F14: 0 | G14: -6 | H14: -1 | I14: 3 | J14: 0 | K14: 0 | L14: 0
... B35: Net Cash Flow | C35: 25 | D35: -202 | E35: 21 | F35: -28 | G35: 2595 | H35: -1374 | I35: -695 | J35: -446 | K35: 111 | L35: 5258

Sheet Data Sheet
A1: COMPANY NAME | B1: HINDUSTAN UNILEVER LTD | E1: =IF(B2<>B3, "A NEW VERSION OF THE WORKSHEET IS AVAILABLE", "")
A2: LATEST VERSION | B2: 2.1 | E2: PLEASE DO NOT MAKE ANY CHANGES TO THIS SHEET
A3: CURRENT VERSION | B3: 2.1
A5: META
A6: Number of shares | B6: =IF(B9>0, B9/B8, 0) -> 234.9591
A7: Face Value | B7: 1
A8: Current Price | B8: 2390.7
A9: Market Capitalization | B9: 561716.73
A15: PROFIT & LOSS
A16: Report Date | B16: 42460 | C16: 42825 | D16: 43190 | E16: 43555 | F16: 43921 | G16: 44286 | H16: 44651 | I16: 45016 | J16: 45382 | K16: 45747
A17: Sales | B17: 32186 | C17: 33162 | D17: 35545 | E17: 39310 | F17: 39783 | G17: 47028 | H17: 52446 | I17: 60580 | J17: 61896 | K17: 63121
A18: Raw Material Cost | B18: 13184 | C18: 13606 | D18: 14233 | E18: 15845 | F18: 15697 | G18: 20141 | H18: 22871 | I18: 28427 | J18: 26822 | K18: 27344
A19: Change in Inventory | B19: -83 | C19: -144 | D19: 72 | E19: -12 | F19: 108 | G19: 405 | H19: 22 | I19: 75 | J19: 11 | K19: 153
A20: Power and Fuel | B20: 309 | C20: 295 | D20: 295 | E20: 308 | F20: 299 | G20: 339 | H20: 318 | I20: 384 | J20: 446 | K20: 427
A21: Other Mfr. Exp | B21: 2966 | C21: 2887 | D21: 2998 | E21: 3041 | F21: 2906 | G21: 2868 | H21: 3354 | I21: 3791 | J21: 3385 | K21: 3834
A22: Employee Cost | B22: 1680 | C22: 1743 | D22: 1860 | E22: 1875 | F22: 1820 | G22: 2358 | H22: 2545 | I22: 2854 | J22: 3009 | K22: 3077
A23: Selling and admin | B23: 6741 | C23: 6689 | D23: 7252 | E23: 7796 | F23: 7620 | G23: 7906 | H23: 8164 | I23: 8785 | J23: 10780 | K23: 10693
A24: Other Expenses | B24: 1313 | C24: 1470 | D24: 1480 | E24: 1553 | F24: 1688 | G24: 2195 | H24: 2359 | I24: 2267 | J24: 2806 | K24: 3056
A25: Other Income | B25: 486 | C25: 606 | D25: 353 | E25: 322 | F25: 424 | G25: 170 | H25: 219 | I25: 448 | J25: 817 | K25: 1322
A26: Depreciation | B26: 353 | C26: 432 | D26: 520 | E26: 565 | F26: 1002 | G26: 1074 | H26: 1091 | I26: 1137 | J26: 1216 | K26: 1355
A27: Interest | B27: 17 | C27: 35 | D27: 26 | E27: 33 | F27: 118 | G27: 117 | H27: 106 | I27: 114 | J27: 334 | K27: 395
... A31: Dividend Amount | B31: 3456 | C31: 3672 | D31: 4320 | E31: 4752 | F31: 5400 | G31: 9517.5 | H31: 7990 | I31: 9165 | J31: 9870 | K31: 12455
A40: Quarters
A41: Report Date | B41: 45107 | C41: 45199 | D41: 45291 | E41: 45382 | F41: 45473 | G41: 45565 | H41: 45657 | I41: 45747 | J41: 45838 | K41: 45930
A42: Sales | B42: 15496 | C42: 15623 | D42: 15567 | E42: 15210 | F42: 15707 | G42: 15926 | H42: 15818 | I42: 15670 | J42: 16514 | K42: 16241
A43: Expenses | B43: 11832 | C43: 11828 | D43: 11902 | E43: 11675 | F43: 11965 | G43: 12139 | H43: 12123 | I43: 12052 | J43: 12797 | K43: 12515
A44: Other Income | B44: 146 | C44: 178 | D44: 184 | E44: 309 | F44: 209 | G44: 203 | H44: 740 | I44: 171 | J44: 74 | K44: 331
A45: Depreciation | B45: 286 | C45: 297 | D45: 313 | E45: 320 | F45: 329 | G45: 338 | H45: 341 | I45: 347 | J45: 361 | K45: 358
A46: Interest | B46: 50 | C46: 88 | D46: 91 | E46: 105 | F46: 93 | G46: 110 | H46: 112 | I46: 80 | J46: 127 | K46: 129
A47: Profit before tax | B47: 3474 | C47: 3588 | D47: 3445 | E47: 3419 | F47: 3529 | G47: 3542 | H47: 3982 | I47: 3362 | J47: 3303 | K47: 3570
A48: Tax | B48: 918 | C48: 931 | D48: 937 | E48: 858 | F48: 917 | G48: 947 | H48: 993 | I48: 887 | J48: 535 | K48: 876
A49: Net profit | B49: 2554 | C49: 2656 | D49: 2509 | E49: 2558 | F49: 2610 | G49: 2591 | H49: 2984 | I49: 2464 | J49: 2756 | K49: 2685
A50: Operating Profit | B50: 3664 | C50: 3795 | D50: 3665 | E50: 3535 | F50: 3742 | G50: 3787 | H50: 3695 | I50: 3618 | J50: 3717 | K50: 3726
A55: BALANCE SHEET
A56: Report Date | B56: 42460 | C56: 42825 | D56: 43190 | E56: 43555 | F56: 43921 | G56: 44286 | H56: 44651 | I56: 45016 | J56: 45382 | K56: 45747
A57: Equity Share Capital | B57: 216 | C57: 216 | D57: 216 | E57: 216 | F57: 216 | G57: 235 | H57: 235 | I57: 235 | J57: 235 | K57: 235
A58: Reserves | B58: 6357 | C58: 6528 | D58: 7065 | E58: 7651 | F58: 8013 | G58: 47439 | H58: 48826 | I58: 50069 | J58: 50983 | K58: 49167
A59: Borrowings | B59: 177 | C59: 277 | E59: 99 | H59: 1043 | I59: 1219 | J59: 1484 | K59: 1648
A60: Other Liabilities | B60: 8043 | C60: 8685 | D60: 10581 | E60: 10663 | F60: 11924 | G60: 21066 | H60: 20402 | I60: 21554 | J60: 25787 | K60: 28813
A61: Total | B61: 14793 | C61: 15706 | D61: 17862 | E61: 18629 | F61: 20153 | G61: 68740 | H61: 70506 | I61: 73077 | J61: 78489 | K61: 79863
...
